Workbook

Sheet README
A1: Talent Market Mapping & Recruitment Research
A2: Sector: Enterprise AI / GenAI & SaaS (India hiring lens) | Compiled: Oct 2026
A4: HOW THE WORKBOOK FLOWS
A5: Companies: 44-company database with standardised fields, filters and a client-fit score
A6: Roles & Skills: 7 roles compared across 21 skills (3 = must-have, 2 = preferred, 1 = nice-to-have, 0 = not needed)
A7: Job Order: sample structured job order (must-have / preferred / disqualifiers) with a weighted candidate scorecard
A8: Sourcing Strategy: channels, LinkedIn Boolean strings, feeder companies, funnel model, outreach template
A9: Insights: formula-driven hiring patterns (by company type, hub, size, role demand) + chart
A10: Client Prospects: top-10 potential client companies, ranked automatically, with outreach angle
A11: Market Report: the short written report (headline numbers update from the data)
A12: Assumptions: scoring weights and lookup tables. Change a weight and every score and ranking updates
A13: Sources: evidence log with links and a source-quality rating for every hiring signal filled in
... A23: Candidates on the Job Order sheet are dummy data for illustration. Use only public professional information when sourcing, respect platform terms of service and India's DPDP Act.

Sheet Companies
A1: ID | B1: Company | C1: Sub-segment | D1: Type | E1: HQ (global) | F1: Primary India hub | G1: Size band | H1: Likely roles hired (R1-R7) | I1: Agency openness (1-5, est.) | J1: Hiring signal (1-5) FILL | K1: Open roles seen (#) FILL | L1: Careers URL FILL | M1: Date checked FILL | N1: Size score | O1: Role breadth | P1: Client fit score | Q1: Rank key (helper) | R1: Notes
A2: C01 | B2: ServiceNow | C2: Enterprise workflow platform | D2: Platform vendor | E2: Santa Clara, US | F2: Hyderabad | G2: Large | H2: R1,R2,R5,R6,R7 | I2: 2 | J2: 5 | K2: 71 | L2: https://careers.servicenow.com/locations/apj/india/ | M2: 46320 | N2: =INDEX(Assumptions!$B$13:$B$15,MATCH(G2,Assumptions!$A$13:$A$15,0)) -> 5 | O2: =ROUND(5*(LEN(H2)-LEN(SUBSTITUTE(H2,",",""))+1)/7,1) -> 3.6 | P2: =ROUND(Assumptions!$B$4*N2+Assumptions!$B$5*O2+Assumptions!$B$6*I2+Assumptions!$B$7*IF(J2="",Assumptions!$B$9,J2),2) -> 3.75 | Q2: =P2+(200-ROW())/100000 -> 3.75198 | R2: Core of the ServiceNow ecosystem; ties to your CAD prep | VERIFIED on careers site 25 Oct 2026: 71 open jobs in India; India page says plans to double the team within a few years. See Sources S9.
A3: C02 | B3: Salesforce | C3: CRM / enterprise platform | D3: Platform vendor | E3: San Francisco, US | F3: Hyderabad | G3: Large | H3: R1,R2,R3,R6,R7 | I3: 2 | J3: 4 | L3: https://careers.salesforce.com/en/jobs/ | M3: 46320 | N3: =INDEX(Assumptions!$B$13:$B$15,MATCH(G3,Assumptions!$A$13:$A$15,0)) -> 5 | O3: =ROUND(5*(LEN(H3)-LEN(SUBSTITUTE(H3,",",""))+1)/7,1) -> 3.6 | P3: =ROUND(Assumptions!$B$4*N3+Assumptions!$B$5*O3+Assumptions!$B$6*I3+Assumptions!$B$7*IF(J3="",Assumptions!$B$9,J3),2) -> 3.55 | Q3: =P3+(200-ROW())/100000 -> 3.55197 | R3: Agentforce push drives GenAI hiring | Official careers site read via search snapshot 25 Oct 2026: about 1,400 jobs listed overall (global count, not India-only); India listings include Agentforce technical manager and architect roles; India page describes an expanded Centre of Excellence and AI-first growth in Hyderabad, Bangalore, Mumbai, Pune, Gurgaon. See Sources S15.
A4: C03 | B4: SAP Labs India | C4: Enterprise software | D4: Platform vendor | E4: Walldorf, Germany | F4: Bengaluru | G4: Large | H4: R1,R2,R4,R6,R7 | I4: 2 | N4: =INDEX(Assumptions!$B$13:$B$15,MATCH(G4,Assumptions!$A$13:$A$15,0)) -> 5 | O4: =ROUND(5*(LEN(H4)-LEN(SUBSTITUTE(H4,",",""))+1)/7,1) -> 3.6 | P4: =ROUND(Assumptions!$B$4*N4+Assumptions!$B$5*O4+Assumptions!$B$6*I4+Assumptions!$B$7*IF(J4="",Assumptions!$B$9,J4),2) -> 3.35 | Q4: =P4+(200-ROW())/100000 -> 3.35196
A5: C04 | B5: Oracle | C5: Enterprise software / cloud | D5: Platform vendor | E5: Austin, US | F5: Bengaluru | G5: Large | H5: R1,R2,R4,R7 | I5: 2 | N5: =INDEX(Assumptions!$B$13:$B$15,MATCH(G5,Assumptions!$A$13:$A$15,0)) -> 5 | O5: =ROUND(5*(LEN(H5)-LEN(SUBSTITUTE(H5,",",""))+1)/7,1) -> 2.9 | P5: =ROUND(Assumptions!$B$4*N5+Assumptions!$B$5*O5+Assumptions!$B$6*I5+Assumptions!$B$7*IF(J5="",Assumptions!$B$9,J5),2) -> 3.18 | Q5: =P5+(200-ROW())/100000 -> 3.18195
A6: C05 | B6: Workday | C6: HR and finance cloud | D6: Platform vendor | E6: Pleasanton, US | F6: Pune | G6: Large | H6: R1,R2,R4,R6 | I6: 2 | N6: =INDEX(Assumptions!$B$13:$B$15,MATCH(G6,Assumptions!$A$13:$A$15,0)) -> 5 | O6: =ROUND(5*(LEN(H6)-LEN(SUBSTITUTE(H6,",",""))+1)/7,1) -> 2.9 | P6: =ROUND(Assumptions!$B$4*N6+Assumptions!$B$5*O6+Assumptions!$B$6*I6+Assumptions!$B$7*IF(J6="",Assumptions!$B$9,J6),2) -> 3.18 | Q6: =P6+(200-ROW())/100000 -> 3.18194
A7: C06 | B7: Adobe | C7: Creative / document cloud | D7: Platform vendor | E7: San Jose, US | F7: NCR | G7: Large | H7: R1,R2,R3,R6 | I7: 2 | J7: 4 | L7: https://www.adobe.com/careers/engineering.html | M7: 46320 | N7: =INDEX(Assumptions!$B$13:$B$15,MATCH(G7,Assumptions!$A$13:$A$15,0)) -> 5 | O7: =ROUND(5*(LEN(H7)-LEN(SUBSTITUTE(H7,",",""))+1)/7,1) -> 2.9 | P7: =ROUND(Assumptions!$B$4*N7+Assumptions!$B$5*O7+Assumptions!$B$6*I7+Assumptions!$B$7*IF(J7="",Assumptions!$B$9,J7),2) -> 3.38 | Q7: =P7+(200-ROW())/100000 -> 3.38193 | R7: Firefly / GenAI product teams | Official careers pages read via search snapshot 25 Oct 2026: engineering and product page shows 500+ jobs (global count, not India-only), with Noida GenAI / ML roles; entry-level '2026 University Graduate - Software Engineer' postings seen on a job board. Secondary sources report a new Noida campus (May 2026). See Sources S19.
A8: C07 | B8: Atlassian | C8: Collaboration SaaS | D8: SaaS product | E8: Sydney, Australia | F8: Bengaluru | G8: Large | H8: R1,R2,R4,R6 | I8: 2 | N8: =INDEX(Assumptions!$B$13:$B$15,MATCH(G8,Assumptions!$A$13:$A$15,0)) -> 5 | O8: =ROUND(5*(LEN(H8)-LEN(SUBSTITUTE(H8,",",""))+1)/7,1) -> 2.9 | P8: =ROUND(Assumptions!$B$4*N8+Assumptions!$B$5*O8+Assumptions!$B$6*I8+Assumptions!$B$7*IF(J8="",Assumptions!$B$9,J8),2) -> 3.18 | Q8: =P8+(200-ROW())/100000 -> 3.18192
A9: C08 | B9: Microsoft (IDC) | C9: Cloud / AI | D9: Platform vendor | E9: Redmond, US | F9: Hyderabad | G9: Large | H9: R1,R2,R3,R6,R7 | I9: 1 | N9: =INDEX(Assumptions!$B$13:$B$15,MATCH(G9,Assumptions!$A$13:$A$15,0)) -> 5 | O9: =ROUND(5*(LEN(H9)-LEN(SUBSTITUTE(H9,",",""))+1)/7,1) -> 3.6 | P9: =ROUND(Assumptions!$B$4*N9+Assumptions!$B$5*O9+Assumptions!$B$6*I9+Assumptions!$B$7*IF(J9="",Assumptions!$B$9,J9),2) -> 3.05 | Q9: =P9+(200-ROW())/100000 -> 3.05191 | R9: Very competitive, brand-led hiring
A10: C09 | B10: Google (India) | C10: Cloud / AI | D10: Platform vendor | E10: Mountain View, US | F10: Bengaluru | G10: Large | H10: R1,R2,R3,R6 | I10: 1 | N10: =INDEX(Assumptions!$B$13:$B$15,MATCH(G10,Assumptions!$A$13:$A$15,0)) -> 5 | O10: =ROUND(5*(LEN(H10)-LEN(SUBSTITUTE(H10,",",""))+1)/7,1) -> 2.9 | P10: =ROUND(Assumptions!$B$4*N10+Assumptions!$B$5*O10+Assumptions!$B$6*I10+Assumptions!$B$7*IF(J10="",Assumptions!$B$9,J10),2) -> 2.88 | Q10: =P10+(200-ROW())/100000 -> 2.8819
A11: C10 | B11: Freshworks | C11: CX / ITSM SaaS | D11: SaaS product | E11: San Mateo, US | F11: Chennai | G11: Mid | H11: R1,R2,R4,R6,R7 | I11: 3 | J11: 3 | K11: 28 | L11: https://careers.smartrecruiters.com/Freshworks/pd | M11: 46320 | N11: =INDEX(Assumptions!$B$13:$B$15,MATCH(G11,Assumptions!$A$13:$A$15,0)) -> 3 | O11: =ROUND(5*(LEN(H11)-LEN(SUBSTITUTE(H11,",",""))+1)/7,1) -> 3.6 | P11: =ROUND(Assumptions!$B$4*N11+Assumptions!$B$5*O11+Assumptions!$B$6*I11+Assumptions!$B$7*IF(J11="",Assumptions!$B$9,J11),2) -> 3.15 | Q11: =P11+(200-ROW())/100000 -> 3.15189 | R11: Direct ITSM competitor to ServiceNow | VERIFIED on official ATS board 25 Oct 2026: 28 India openings (Bengaluru 12, Chennai 12, Hyderabad 4), almost all Senior/Staff/Lead/Principal, so not fresher-friendly. See Sources S11.
A12: C11 | B12: Zoho | C12: Business SaaS suite | D12: SaaS product | E12: Chennai, India | F12: Chennai | G12: Large | H12: R1,R2,R3,R6 | I12: 1 | N12: =INDEX(Assumptions!$B$13:$B$15,MATCH(G12,Assumptions!$A$13:$A$15,0)) -> 5 | O12: =ROUND(5*(LEN(H12)-LEN(SUBSTITUTE(H12,",",""))+1)/7,1) -> 2.9 | P12: =ROUND(Assumptions!$B$4*N12+Assumptions!$B$5*O12+Assumptions!$B$6*I12+Assumptions!$B$7*IF(J12="",Assumptions!$B$9,J12),2) -> 2.88 | Q12: =P12+(200-ROW())/100000 -> 2.88188 | R12: Hires heavily from own campus pipeline
A13: C12 | B13: Postman | C13: API platform | D13: SaaS product | E13: San Francisco, US | F13: Bengaluru | G13: Mid | H13: R1,R2,R6 | I13: 1 | J13: 3 | M13: 46320 | N13: =INDEX(Assumptions!$B$13:$B$15,MATCH(G13,Assumptions!$A$13:$A$15,0)) -> 3 | O13: =ROUND(5*(LEN(H13)-LEN(SUBSTITUTE(H13,",",""))+1)/7,1) -> 2.1 | P13: =ROUND(Assumptions!$B$4*N13+Assumptions!$B$5*O13+Assumptions!$B$6*I13+Assumptions!$B$7*IF(J13="",Assumptions!$B$9,J13),2) -> 2.18 | Q13: =P13+(200-ROW())/100000 -> 2.18187 | R13: 25 Oct 2026: several current Bengaluru roles (AI Infrastructure Manager, Engineering Manager Postman AI, frontend engineer) on job boards; no official count. Job posts say Postman does NOT accept unsolicited agency resumes, so agency openness set to 1: needs a signed agreement first. See Sources S13.
A14: C13 | B14: Chargebee | C14: Subscription billing | D14: SaaS product | E14: San Francisco, US | F14: Chennai | G14: Mid | H14: R2,R4,R6 | I14: 3 | N14: =INDEX(Assumptions!$B$13:$B$15,MATCH(G14,Assumptions!$A$13:$A$15,0)) -> 3 | O14: =ROUND(5*(LEN(H14)-LEN(SUBSTITUTE(H14,",",""))+1)/7,1) -> 2.1 | P14: =ROUND(Assumptions!$B$4*N14+Assumptions!$B$5*O14+Assumptions!$B$6*I14+Assumptions!$B$7*IF(J14="",Assumptions!$B$9,J14),2) -> 2.78 | Q14: =P14+(200-ROW())/100000 -> 2.78186
A15: C14 | B15: Razorpay | C15: Payments / fintech | D15: SaaS product | E15: Bengaluru, India | F15: Bengaluru | G15: Mid | H15: R2,R3,R4,R6 | I15: 3 | J15: 3 | M15: 46320 | N15: =INDEX(Assumptions!$B$13:$B$15,MATCH(G15,Assumptions!$A$13:$A$15,0)) -> 3 | O15: =ROUND(5*(LEN(H15)-LEN(SUBSTITUTE(H15,",",""))+1)/7,1) -> 2.9 | P15: =ROUND(Assumptions!$B$4*N15+Assumptions!$B$5*O15+Assumptions!$B$6*I15+Assumptions!$B$7*IF(J15="",Assumptions!$B$9,J15),2) -> 2.98 | Q15: =P15+(200-ROW())/100000 -> 2.98185 | R15: Mixed evidence 25 Oct 2026: aggregator counts disagree widely (about 3 to 10 on some, about 60 on another); ATS is Greenhouse with senior engineering and talent-partner roles; entry roles seen are mostly analysts and interns. Treat count as unknown. See Sources S16.
A16: C15 | B16: Darwinbox | C16: HR tech | D16: SaaS product | E16: Hyderabad, India | F16: Hyderabad | G16: Mid | H16: R1,R3,R4,R6 | I16: 3 | N16: =INDEX(Assumptions!$B$13:$B$15,MATCH(G16,Assumptions!$A$13:$A$15,0)) -> 3 | O16: =ROUND(5*(LEN(H16)-LEN(SUBSTITUTE(H16,",",""))+1)/7,1) -> 2.9 | P16: =ROUND(Assumptions!$B$4*N16+Assumptions!$B$5*O16+Assumptions!$B$6*I16+Assumptions!$B$7*IF(J16="",Assumptions!$B$9,J16),2) -> 2.98 | Q16: =P16+(200-ROW())/100000 -> 2.98184
A17: C16 | B17: Leena AI | C17: Enterprise GenAI agents | D17: AI startup | E17: US / Bengaluru | F17: Bengaluru | G17: Small | H17: R1,R2,R6,R7 | I17: 4 | J17: 2 | K17: 1 | M17: 46320 | N17: =INDEX(Assumptions!$B$13:$B$15,MATCH(G17,Assumptions!$A$13:$A$15,0)) -> 2 | O17: =ROUND(5*(LEN(H17)-LEN(SUBSTITUTE(H17,",",""))+1)/7,1) -> 2.9 | P17: =ROUND(Assumptions!$B$4*N17+Assumptions!$B$5*O17+Assumptions!$B$6*I17+Assumptions!$B$7*IF(J17="",Assumptions!$B$9,J17),2) -> 2.83 | Q17: =P17+(200-ROW())/100000 -> 2.83183 | R17: Employee-service automation, overlaps ITSM space | 25 Oct 2026: few openings (1 role pulled from its ATS; job boards show mainly sales and US roles plus a Bengaluru delivery / forward-deployed engineering role). Company pages also list a Gurugram office, so hub may be NCR. See Sources S17.
A18: C17 | B18: Whatfix | C18: Digital adoption platform | D18: SaaS product | E18: San Jose, US | F18: Bengaluru | G18: Mid | H18: R1,R2,R6,R7 | I18: 3 | N18: =INDEX(Assumptions!$B$13:$B$15,MATCH(G18,Assumptions!$A$13:$A$15,0)) -> 3 | O18: =ROUND(5*(LEN(H18)-LEN(SUBSTITUTE(H18,",",""))+1)/7,1) -> 2.9 | P18: =ROUND(Assumptions!$B$4*N18+Assumptions!$B$5*O18+Assumptions!$B$6*I18+Assumptions!$B$7*IF(J18="",Assumptions!$B$9,J18),2) -> 2.98 | Q18: =P18+(200-ROW())/100000 -> 2.98182
A19: C18 | B19: BrowserStack | C19: Software testing platform | D19: SaaS product | E19: Dublin / Mumbai | F19: Mumbai | G19: Mid | H19: R2,R4,R6 | I19: 3 | N19: =INDEX(Assumptions!$B$13:$B$15,MATCH(G19,Assumptions!$A$13:$A$15,0)) -> 3 | O19: =ROUND(5*(LEN(H19)-LEN(SUBSTITUTE(H19,",",""))+1)/7,1) -> 2.1 | P19: =ROUND(Assumptions!$B$4*N19+Assumptions!$B$5*O19+Assumptions!$B$6*I19+Assumptions!$B$7*IF(J19="",Assumptions!$B$9,J19),2) -> 2.78 | Q19: =P19+(200-ROW())/100000 -> 2.78181
A20: C19 | B20: CleverTap | C20: Customer engagement | D20: SaaS product | E20: Mountain View / Mumbai | F20: Mumbai | G20: Small | H20: R2,R3,R4 | I20: 3 | N20: =INDEX(Assumptions!$B$13:$B$15,MATCH(G20,Assumptions!$A$13:$A$15,0)) -> 2 | O20: =ROUND(5*(LEN(H20)-LEN(SUBSTITUTE(H20,",",""))+1)/7,1) -> 2.1 | P20: =ROUND(Assumptions!$B$4*N20+Assumptions!$B$5*O20+Assumptions!$B$6*I20+Assumptions!$B$7*IF(J20="",Assumptions!$B$9,J20),2) -> 2.53 | Q20: =P20+(200-ROW())/100000 -> 2.5318
A21: C20 | B21: MoEngage | C21: Customer engagement | D21: SaaS product | E21: San Francisco / Bengaluru | F21: Bengaluru | G21: Mid | H21: R1,R2,R3,R4 | I21: 3 | N21: =INDEX(Assumptions!$B$13:$B$15,MATCH(G21,Assumptions!$A$13:$A$15,0)) -> 3 | O21: =ROUND(5*(LEN(H21)-LEN(SUBSTITUTE(H21,",",""))+1)/7,1) -> 2.9 | P21: =ROUND(Assumptions!$B$4*N21+Assumptions!$B$5*O21+Assumptions!$B$6*I21+Assumptions!$B$7*IF(J21="",Assumptions!$B$9,J21),2) -> 2.98 | Q21: =P21+(200-ROW())/100000 -> 2.98179
A22: C21 | B22: Innovaccer | C22: Healthcare data and AI | D22: AI SaaS | E22: San Francisco, US | F22: NCR | G22: Mid | H22: R1,R2,R3,R4,R7 | I22: 3 | J22: 4 | K22: 44 | M22: 46320 | N22: =INDEX(Assumptions!$B$13:$B$15,MATCH(G22,Assumptions!$A$13:$A$15,0)) -> 3 | O22: =ROUND(5*(LEN(H22)-LEN(SUBSTITUTE(H22,",",""))+1)/7,1) -> 3.6 | P22: =ROUND(Assumptions!$B$4*N22+Assumptions!$B$5*O22+Assumptions!$B$6*I22+Assumptions!$B$7*IF(J22="",Assumptions!$B$9,J22),2) -> 3.35 | Q22: =P22+(200-ROW())/100000 -> 3.35178 | R22: Large Noida base; relevant to your MediGenius work | Greenhouse board postings and a job-board mirror 25 Oct 2026: about 44 jobs in total (global, roughly half Noida on-site); includes apprentice roles (Data Ops Engineer, Talent Acquisition) that suit entry-level candidates; runs some in-house talent acquisition. See Sources S20.
A23: C22 | B23: Uniphore | C23: Conversational / enterprise AI | D23: AI SaaS | E23: Palo Alto, US | F23: Chennai | G23: Mid | H23: R1,R2,R3,R6 | I23: 3 | N23: =INDEX(Assumptions!$B$13:$B$15,MATCH(G23,Assumptions!$A$13:$A$15,0)) -> 3 | O23: =ROUND(5*(LEN(H23)-LEN(SUBSTITUTE(H23,",",""))+1)/7,1) -> 2.9 | P23: =ROUND(Assumptions!$B$4*N23+Assumptions!$B$5*O23+Assumptions!$B$6*I23+Assumptions!$B$7*IF(J23="",Assumptions!$B$9,J23),2) -> 2.98 | Q23: =P23+(200-ROW())/100000 -> 2.98177
A24: C23 | B24: Observe.AI | C24: Contact-centre AI | D24: AI SaaS | E24: San Francisco, US | F24: Bengaluru | G24: Small | H24: R1,R2,R3,R6 | I24: 4 | N24: =INDEX(Assumptions!$B$13:$B$15,MATCH(G24,Assumptions!$A$13:$A$15,0)) -> 2 | O24: =ROUND(5*(LEN(H24)-LEN(SUBSTITUTE(H24,",",""))+1)/7,1) -> 2.9 | P24: =ROUND(Assumptions!$B$4*N24+Assumptions!$B$5*O24+Assumptions!$B$6*I24+Assumptions!$B$7*IF(J24="",Assumptions!$B$9,J24),2) -> 3.03 | Q24: =P24+(200-ROW())/100000 -> 3.03176
A25: C24 | B25: Yellow.ai | C25: Conversational AI | D25: AI SaaS | E25: San Francisco, US | F25: Bengaluru | G25: Mid | H25: R1,R2,R6,R7 | I25: 4 | J25: 3 | L25: https://yellow.ai/careers | M25: 46320 | N25: =INDEX(Assumptions!$B$13:$B$15,MATCH(G25,Assumptions!$A$13:$A$15,0)) -> 3 | O25: =ROUND(5*(LEN(H25)-LEN(SUBSTITUTE(H25,",",""))+1)/7,1) -> 2.9 | P25: =ROUND(Assumptions!$B$4*N25+Assumptions!$B$5*O25+Assumptions!$B$6*I25+Assumptions!$B$7*IF(J25="",Assumptions!$B$9,J25),2) -> 3.28 | Q25: =P25+(200-ROW())/100000 -> 3.28175 | R25: WEAK evidence 25 Oct 2026: only job-board and training-site listings (GenAI intern roles in many cities, early-career AI engineer posts); no official count read. See Sources S12.
A26: C25 | B26: Gupshup | C26: Conversational messaging | D26: SaaS product | E26: San Francisco, US | F26: Bengaluru | G26: Mid | H26: R1,R2,R4 | I26: 4 | N26: =INDEX(Assumptions!$B$13:$B$15,MATCH(G26,Assumptions!$A$13:$A$15,0)) -> 3 | O26: =ROUND(5*(LEN(H26)-LEN(SUBSTITUTE(H26,",",""))+1)/7,1) -> 2.1 | P26: =ROUND(Assumptions!$B$4*N26+Assumptions!$B$5*O26+Assumptions!$B$6*I26+Assumptions!$B$7*IF(J26="",Assumptions!$B$9,J26),2) -> 3.08 | Q26: =P26+(200-ROW())/100000 -> 3.08174
A27: C26 | B27: Sprinklr | C27: Customer experience platform | D27: SaaS product | E27: New York, US | F27: NCR | G27: Mid | H27: R1,R2,R3,R6 | I27: 3 | N27: =INDEX(Assumptions!$B$13:$B$15,MATCH(G27,Assumptions!$A$13:$A$15,0)) -> 3 | O27: =ROUND(5*(LEN(H27)-LEN(SUBSTITUTE(H27,",",""))+1)/7,1) -> 2.9 | P27: =ROUND(Assumptions!$B$4*N27+Assumptions!$B$5*O27+Assumptions!$B$6*I27+Assumptions!$B$7*IF(J27="",Assumptions!$B$9,J27),2) -> 2.98 | Q27: =P27+(200-ROW())/100000 -> 2.98173
A28: C27 | B28: Sarvam AI | C28: Indic LLMs | D28: AI startup | E28: Bengaluru, India | F28: Bengaluru | G28: Small | H28: R1,R2,R3 | I28: 4 | J28: 5 | K28: 61 | L28: https://www.sarvam.ai/careers | M28: 46320 | N28: =INDEX(Assumptions!$B$13:$B$15,MATCH(G28,Assumptions!$A$13:$A$15,0)) -> 2 | O28: =ROUND(5*(LEN(H28)-LEN(SUBSTITUTE(H28,",",""))+1)/7,1) -> 2.1 | P28: =ROUND(Assumptions!$B$4*N28+Assumptions!$B$5*O28+Assumptions!$B$6*I28+Assumptions!$B$7*IF(J28="",Assumptions!$B$9,J28),2) -> 3.23 | Q28: =P28+(200-ROW())/100000 -> 3.23172 | R28: Frontier-style research and applied roles | VERIFIED on careers page 25 Oct 2026: 61 open positions (30 engineering, 12 sales/GTM), mostly Bengaluru on-site. Also $234M Series B (Jun 2026). See Sources S5, S10.
A29: C28 | B29: Krutrim | C29: Indic LLMs / AI cloud | D29: AI startup | E29: Bengaluru, India | F29: Bengaluru | G29: Mid | H29: R1,R2,R4 | I29: 4 | N29: =INDEX(Assumptions!$B$13:$B$15,MATCH(G29,Assumptions!$A$13:$A$15,0)) -> 3 | O29: =ROUND(5*(LEN(H29)-LEN(SUBSTITUTE(H29,",",""))+1)/7,1) -> 2.1 | P29: =ROUND(Assumptions!$B$4*N29+Assumptions!$B$5*O29+Assumptions!$B$6*I29+Assumptions!$B$7*IF(J29="",Assumptions!$B$9,J29),2) -> 3.08 | Q29: =P29+(200-ROW())/100000 -> 3.08171
A30: C29 | B30: Gnani.ai | C30: Voice AI | D30: AI startup | E30: Bengaluru, India | F30: Bengaluru | G30: Small | H30: R1,R2,R3 | I30: 4 | N30: =INDEX(Assumptions!$B$13:$B$15,MATCH(G30,Assumptions!$A$13:$A$15,0)) -> 2 | O30: =ROUND(5*(LEN(H30)-LEN(SUBSTITUTE(H30,",",""))+1)/7,1) -> 2.1 | P30: =ROUND(Assumptions!$B$4*N30+Assumptions!$B$5*O30+Assumptions!$B$6*I30+Assumptions!$B$7*IF(J30="",Assumptions!$B$9,J30),2) -> 2.83 | Q30: =P30+(200-ROW())/100000 -> 2.8317
A31: C30 | B31: Haptik | C31: Conversational AI | D31: AI startup | E31: Mumbai, India | F31: Mumbai | G31: Small | H31: R1,R2,R7 | I31: 4 | N31: =INDEX(Assumptions!$B$13:$B$15,MATCH(G31,Assumptions!$A$13:$A$15,0)) -> 2 | O31: =ROUND(5*(LEN(H31)-LEN(SUBSTITUTE(H31,",",""))+1)/7,1) -> 2.1 | P31: =ROUND(Assumptions!$B$4*N31+Assumptions!$B$5*O31+Assumptions!$B$6*I31+Assumptions!$B$7*IF(J31="",Assumptions!$B$9,J31),2) -> 2.83 | Q31: =P31+(200-ROW())/100000 -> 2.83169
A32: C31 | B32: Fractal Analytics | C32: AI and analytics services | D32: Analytics & AI services | E32: Mumbai, India | F32: Mumbai | G32: Mid | H32: R1,R2,R3,R4,R6,R7 | I32: 3 | J32: 4 | K32: 68 | M32: 46320 | N32: =INDEX(Assumptions!$B$13:$B$15,MATCH(G32,Assumptions!$A$13:$A$15,0)) -> 3 | O32: =ROUND(5*(LEN(H32)-LEN(SUBSTITUTE(H32,",",""))+1)/7,1) -> 4.3 | P32: =ROUND(Assumptions!$B$4*N32+Assumptions!$B$5*O32+Assumptions!$B$6*I32+Assumptions!$B$7*IF(J32="",Assumptions!$B$9,J32),2) -> 3.53 | Q32: =P32+(200-ROW())/100000 -> 3.53168 | R32: Large entry-level analyst intake | 25 Oct 2026: 68 jobs listed on Indeed (not official), spread across Bengaluru, Mumbai, Gurugram; includes an agentic/GenAI platform architect role; mostly mid-senior titles. See Sources S14.
A33: C32 | B33: Tiger Analytics | C33: Analytics services | D33: Analytics & AI services | E33: Santa Clara, US | F33: Chennai | G33: Mid | H33: R2,R3,R4,R7 | I33: 4 | N33: =INDEX(Assumptions!$B$13:$B$15,MATCH(G33,Assumptions!$A$13:$A$15,0)) -> 3 | O33: =ROUND(5*(LEN(H33)-LEN(SUBSTITUTE(H33,",",""))+1)/7,1) -> 2.9 | P33: =ROUND(Assumptions!$B$4*N33+Assumptions!$B$5*O33+Assumptions!$B$6*I33+Assumptions!$B$7*IF(J33="",Assumptions!$B$9,J33),2) -> 3.28 | Q33: =P33+(200-ROW())/100000 -> 3.28167
A34: C33 | B34: LatentView Analytics | C34: Analytics services | D34: Analytics & AI services | E34: Chennai, India | F34: Chennai | G34: Mid | H34: R3,R4,R7 | I34: 4 | N34: =INDEX(Assumptions!$B$13:$B$15,MATCH(G34,Assumptions!$A$13:$A$15,0)) -> 3 | O34: =ROUND(5*(LEN(H34)-LEN(SUBSTITUTE(H34,",",""))+1)/7,1) -> 2.1 | P34: =ROUND(Assumptions!$B$4*N34+Assumptions!$B$5*O34+Assumptions!$B$6*I34+Assumptions!$B$7*IF(J34="",Assumptions!$B$9,J34),2) -> 3.08 | Q34: =P34+(200-ROW())/100000 -> 3.08166
A35: C34 | B35: Tredence | C35: AI and analytics services | D35: Analytics & AI services | E35: San Jose, US | F35: Bengaluru | G35: Mid | H35: R1,R2,R3,R4 | I35: 4 | N35: =INDEX(Assumptions!$B$13:$B$15,MATCH(G35,Assumptions!$A$13:$A$15,0)) -> 3 | O35: =ROUND(5*(LEN(H35)-LEN(SUBSTITUTE(H35,",",""))+1)/7,1) -> 2.9 | P35: =ROUND(Assumptions!$B$4*N35+Assumptions!$B$5*O35+Assumptions!$B$6*I35+Assumptions!$B$7*IF(J35="",Assumptions!$B$9,J35),2) -> 3.28 | Q35: =P35+(200-ROW())/100000 -> 3.28165
A36: C35 | B36: Deloitte | C36: Consulting / ServiceNow partner | D36: IT services | E36: London, UK | F36: Hyderabad | G36: Large | H36: R1,R3,R5,R6,R7 | I36: 3 | J36: 5 | K36: 1500 | L36: https://usijobs.deloitte.com/careersUSI/SearchJobs/ | M36: 46320 | N36: =INDEX(Assumptions!$B$13:$B$15,MATCH(G36,Assumptions!$A$13:$A$15,0)) -> 5 | O36: =ROUND(5*(LEN(H36)-LEN(SUBSTITUTE(H36,",",""))+1)/7,1) -> 3.6 | P36: =ROUND(Assumptions!$B$4*N36+Assumptions!$B$5*O36+Assumptions!$B$6*I36+Assumptions!$B$7*IF(J36="",Assumptions!$B$9,J36),2) -> 4.05 | Q36: =P36+(200-ROW())/100000 -> 4.05164 | R36: Matches your hackathon experience | Official US-India portal read via search snapshots 25 Oct 2026: current listings include ServiceNow roles (HRSD Developer, GRC/IRM, Platform Architect, SRE) and GenAI roles (Python Gen AI Engineer, Gen AI Full Stack, AI Engineer), mostly Hyderabad. The 1,500+ India openings figure is reported by a job-board article citing Deloitte's South Asia site, and the ~50,000 India hiring plan comes from a news site: treat both as unverified. See Sources S18.
A37: C36 | B37: Accenture | C37: IT services / ServiceNow partner | D37: IT services | E37: Dublin, Ireland | F37: Bengaluru | G37: Large | H37: R1,R2,R3,R4,R5,R7 | I37: 3 | J37: 4 | K37: 3 | L37: https://www.accenture.com/in-en/careers | M37: 46320 | N37: =INDEX(Assumptions!$B$13:$B$15,MATCH(G37,Assumptions!$A$13:$A$15,0)) -> 5 | O37: =ROUND(5*(LEN(H37)-LEN(SUBSTITUTE(H37,",",""))+1)/7,1) -> 4.3 | P37: =ROUND(Assumptions!$B$4*N37+Assumptions!$B$5*O37+Assumptions!$B$6*I37+Assumptions!$B$7*IF(J37="",Assumptions!$B$9,J37),2) -> 4.03 | Q37: =P37+(200-ROW())/100000 -> 4.03163 | R37: Evidence: active AI/GenAI fresher roles (LLM Full Stack Engineer, Data Science Associate, AI/ML Associate) seen on job aggregators; FY26 GenAI fresher push. See Sources S1-S3.
A38: C37 | B38: TCS | C38: IT services / ServiceNow partner | D38: IT services | E38: Mumbai, India | F38: Mumbai | G38: Large | H38: R1,R2,R3,R4,R5,R7 | I38: 3 | J38: 3 | L38: https://www.tcs.com/careers | M38: 46320 | N38: =INDEX(Assumptions!$B$13:$B$15,MATCH(G38,Assumptions!$A$13:$A$15,0)) -> 5 | O38: =ROUND(5*(LEN(H38)-LEN(SUBSTITUTE(H38,",",""))+1)/7,1) -> 4.3 | P38: =ROUND(Assumptions!$B$4*N38+Assumptions!$B$5*O38+Assumptions!$B$6*I38+Assumptions!$B$7*IF(J38="",Assumptions!$B$9,J38),2) -> 3.83 | Q38: =P38+(200-ROW())/100000 -> 3.83162 | R38: Evidence: FY27 fresher plan ~25k vs 40-42k earlier; Q1 FY27 headcount +9,279. See Sources S4.
A39: C38 | B39: Infosys | C39: IT services / ServiceNow partner | D39: IT services | E39: Bengaluru, India | F39: Bengaluru | G39: Large | H39: R1,R2,R3,R4,R5,R7 | I39: 3 | J39: 3 | L39: https://www.infosys.com/careers/ | M39: 46320 | N39: =INDEX(Assumptions!$B$13:$B$15,MATCH(G39,Assumptions!$A$13:$A$15,0)) -> 5 | O39: =ROUND(5*(LEN(H39)-LEN(SUBSTITUTE(H39,",",""))+1)/7,1) -> 4.3 | P39: =ROUND(Assumptions!$B$4*N39+Assumptions!$B$5*O39+Assumptions!$B$6*I39+Assumptions!$B$7*IF(J39="",Assumptions!$B$9,J39),2) -> 3.83 | Q39: =P39+(200-ROW())/100000 -> 3.83161 | R39: Evidence: plans ~20k freshers in FY27; headcount -532 in Q1 FY27. See Sources S4.
A40: C39 | B40: Wipro | C40: IT services / ServiceNow partner | D40: IT services | E40: Bengaluru, India | F40: Bengaluru | G40: Large | H40: R1,R2,R4,R5,R7 | I40: 3 | J40: 3 | L40: https://careers.wipro.com/ | M40: 46320 | N40: =INDEX(Assumptions!$B$13:$B$15,MATCH(G40,Assumptions!$A$13:$A$15,0)) -> 5 | O40: =ROUND(5*(LEN(H40)-LEN(SUBSTITUTE(H40,",",""))+1)/7,1) -> 3.6 | P40: =ROUND(Assumptions!$B$4*N40+Assumptions!$B$5*O40+Assumptions!$B$6*I40+Assumptions!$B$7*IF(J40="",Assumptions!$B$9,J40),2) -> 3.65 | Q40: =P40+(200-ROW())/100000 -> 3.6516 | R40: Evidence: Q1 FY27 headcount +888; no fresher number disclosed. See Sources S4.
...

Sheet Roles & Skills
A1: Role comparison (5-8 roles) and skills matrix
A3: Code | B3: Role | C3: Typical titles | D3: Typical entry route | E3: Where it is hired most | F3: Fresher-friendliness (1-5, est.) | G3: # Must-have skills | H3: # Preferred skills | I3: # Nice-to-have skills
A4: R1 | B4: GenAI / LLM Engineer | C4: GenAI Engineer, LLM Application Developer, AI Engineer | D4: B.Tech + deployed LLM / RAG projects; internships at AI startups | E4: AI startups, AI SaaS, platform vendors, IT services AI labs | F4: 3 | G4: =COUNTIF(C14:C34,3) -> 5 | H4: =COUNTIF(C14:C34,2) -> 6 | I4: =COUNTIF(C14:C34,1) -> 6
A5: R2 | B5: ML Engineer / MLOps | C5: ML Engineer, MLOps Engineer, Applied Scientist | D5: B.Tech/M.Tech + model deployment experience | E5: Platform vendors, AI SaaS, GCCs | F5: 3 | G5: =COUNTIF(D14:D34,3) -> 6 | H5: =COUNTIF(D14:D34,2) -> 6 | I5: =COUNTIF(D14:D34,1) -> 4
A6: R3 | B6: Data Scientist | C6: Data Scientist, Decision Scientist, Analytics Associate | D6: B.Tech/stats degrees; analytics internships; campus intake at analytics firms | E6: Analytics services, fintech / SaaS, GCCs | F6: 4 | G6: =COUNTIF(E14:E34,3) -> 4 | H6: =COUNTIF(E14:E34,2) -> 4 | I6: =COUNTIF(E14:E34,1) -> 6
A7: R4 | B7: Data Engineer | C7: Data Engineer, Analytics Engineer, Big Data Engineer | D7: B.Tech with SQL, pipelines and cloud projects | E7: IT services, SaaS, GCCs, analytics firms | F7: 4 | G7: =COUNTIF(F14:F34,3) -> 5 | H7: =COUNTIF(F14:F34,2) -> 1 | I7: =COUNTIF(F14:F34,1) -> 5
A8: R5 | B8: ServiceNow Developer | C8: ServiceNow Developer, ITSM Developer, Platform Engineer | D8: CAD certification + hands-on instance work; partner-firm graduate programmes | E8: IT services partners, ServiceNow itself, consulting | F8: 4 | G8: =COUNTIF(G14:G34,3) -> 3 | H8: =COUNTIF(G14:G34,2) -> 2 | I8: =COUNTIF(G14:G34,1) -> 5
A9: R6 | B9: AI Product Manager | C9: Associate PM (AI), Technical PM, Product Analyst | D9: APM programmes, product internships, or tech background with shipped projects | E9: Product / SaaS firms, platform vendors, AI startups | F9: 2 | G9: =COUNTIF(H14:H34,3) -> 2 | H9: =COUNTIF(H14:H34,2) -> 7 | I9: =COUNTIF(H14:H34,1) -> 6
A10: R7 | B10: Solutions Consultant / Pre-sales | C10: Solutions Engineer, Technical Consultant, Pre-sales Engineer | D10: Tech degree + strong communication; consulting / services graduate roles | E10: IT services, SaaS vendors, analytics services | F10: 3 | G10: =COUNTIF(I14:I34,3) -> 2 | H10: =COUNTIF(I14:I34,2) -> 5 | I10: =COUNTIF(I14:I34,1) -> 7
A12: Skills matrix: 3 = must-have, 2 = preferred, 1 = nice-to-have, 0 = not needed (analyst judgement; validate against live job descriptions)
A13: Skill | B13: Category | C13: GenAI / LLM Engineer | D13: ML Engineer / MLOps | E13: Data Scientist | F13: Data Engineer | G13: ServiceNow Developer | H13: AI Product Manager | I13: Solutions Consultant / Pre-sales
A14: Python | B14: Programming | C14: 3 | D14: 3 | E14: 3 | F14: 3 | G14: 1 | H14: 1 | I14: 1
A15: SQL | B15: Data | C15: 2 | D15: 2 | E15: 3 | F15: 3 | G15: 1 | H15: 2 | I15: 2
A16: PyTorch / TensorFlow | B16: ML | C16: 2 | D16: 3 | E16: 2 | F16: 0 | G16: 0 | H16: 0 | I16: 0
A17: Classical ML (scikit-learn, XGBoost) | B17: ML | C17: 1 | D17: 3 | E17: 3 | F17: 0 | G17: 0 | H17: 1 | I17: 0
A18: LLM APIs and prompt engineering | B18: GenAI | C18: 3 | D18: 1 | E18: 1 | F18: 0 | G18: 1 | H18: 2 | I18: 2
A19: RAG and vector databases | B19: GenAI | C19: 3 | D19: 1 | E19: 0 | F19: 1 | G19: 0 | H19: 2 | I19: 1
A20: Agent frameworks (LangChain, LlamaIndex) | B20: GenAI | C20: 3 | D20: 1 | E20: 0 | F20: 0 | G20: 0 | H20: 2 | I20: 1
A21: Fine-tuning (LoRA / PEFT) | B21: GenAI | C21: 2 | D21: 2 | E21: 1 | F21: 0 | G21: 0 | H21: 0 | I21: 0
A22: Model evaluation and responsible AI | B22: GenAI | C22: 3 | D22: 2 | E22: 2 | F22: 0 | G22: 0 | H22: 2 | I22: 1
A23: MLOps (Docker, CI/CD, MLflow) | B23: Engineering | C23: 1 | D23: 3 | E23: 0 | F23: 1 | G23: 0 | H23: 0 | I23: 0
A24: Cloud (AWS / Azure / GCP) | B24: Engineering | C24: 2 | D24: 3 | E24: 1 | F24: 3 | G24: 1 | H24: 1 | I24: 2
A25: Data pipelines (Spark, Airflow, dbt) | B25: Data | C25: 1 | D25: 2 | E25: 1 | F25: 3 | G25: 0 | H25: 0 | I25: 0
... A34: Technical presales and demos | B34: Client-facing | C34: 0 | D34: 0 | E34: 0 | F34: 0 | G34: 1 | H34: 1 | I34: 3

Sheet Job Order
A1: Sample structured job order (illustrative, anonymised client)
A3: Client | B3: Client X: Series-C B2B SaaS company (anonymised sample)
A4: Role | B4: Associate GenAI Engineer (maps to R1 in Roles & Skills)
A5: Location | B5: Bengaluru, hybrid (3 days in office)
A6: Headcount | B6: 2
A7: Experience | B7: 1-3 years (strong final-year / early-career candidates considered)
A8: Reports to | B8: Engineering Manager, AI Platform
A9: Business context | B9: Building LLM-powered support and workflow automation features; moving prototypes to production
A10: Compensation | B10: To be confirmed with client; benchmark against market before outreach
A11: Interview process | B11: Recruiter screen, technical screen (Python + LLM design), take-home or live RAG exercise, hiring manager round
A12: Disqualifiers | B12: No hands-on LLM project; only notebooks with nothing deployed; notice period beyond client limit
A15: # | B15: Criterion | C15: Type | D15: Weight | E15: How to verify from public information | F15: Candidate A (dummy) | G15: Candidate B (dummy) | H15: Candidate C (dummy)
A16: 1 | B16: Python, 1+ years professional or substantial project use | C16: Must | D16: 5 | E16: GitHub repos, LinkedIn skills and project descriptions | F16: 1 | G16: 1 | H16: 1
A17: 2 | B17: Built and shipped an LLM-powered application (API-based or open-source) | C17: Must | D17: 5 | E17: GitHub README, demo links, project write-ups | F17: 1 | G17: 0 | H17: 1
A18: 3 | B18: Hands-on RAG with a vector database | C18: Must | D18: 5 | E18: Repo dependencies, blog posts, project descriptions | F18: 1 | G18: 1 | H18: 1
A19: 4 | B19: REST API development (FastAPI / Flask) | C19: Must | D19: 5 | E19: GitHub code, project stack listed | F19: 1 | G19: 1 | H19: 1
A20: 5 | B20: Git and basic cloud deployment | C20: Must | D20: 5 | E20: Commit history, deployed demo URLs | F20: 1 | G20: 1 | H20: 1
A21: 6 | B21: B.Tech / equivalent in CS or related field | C21: Must | D21: 5 | E21: LinkedIn education | F21: 1 | G21: 1 | H21: 1
A22: 7 | B22: LangChain / LlamaIndex or agent frameworks | C22: Preferred | D22: 2 | E22: Repo imports, project descriptions | F22: 1 | G22: 1 | H22: 0
A23: 8 | B23: LLM evaluation (RAGAS, custom eval harness) | C23: Preferred | D23: 2 | E23: Project write-ups, blog posts | F23: 1 | G23: 0 | H23: 0
A24: 9 | B24: Fine-tuning experience (LoRA / PEFT) | C24: Preferred | D24: 2 | E24: Hugging Face profile, repos | F24: 0 | G24: 0 | H24: 0
A25: 10 | B25: Docker and CI/CD | C25: Preferred | D25: 2 | E25: Dockerfiles and workflow files in repos | F25: 1 | G25: 1 | H25: 0
A26: 11 | B26: Prior SaaS / startup exposure | C26: Preferred | D26: 2 | E26: LinkedIn experience, internships | F26: 0 | G26: 1 | H26: 0
A27: 12 | B27: Public portfolio (GitHub, Kaggle, Hugging Face, blog) | C27: Preferred | D27: 2 | E27: Profile links | F27: 1 | G27: 1 | H27: 1
B29: Weighted score | F29: =SUMPRODUCT($D$16:$D$27,F16:F27)/SUM($D$16:$D$27) -> 0.9047619 | G29: =SUMPRODUCT($D$16:$D$27,G16:G27)/SUM($D$16:$D$27) -> 0.78571429 | H29: =SUMPRODUCT($D$16:$D$27,H16:H27)/SUM($D$16:$D$27) -> 0.76190476
B30: Must-have gate | F30: =IF(COUNTIFS($C$16:$C$27,"Must",F16:F27,0)=0,"Pass","Fail") -> Pass | G30: =IF(COUNTIFS($C$16:$C$27,"Must",G16:G27,0)=0,"Pass","Fail") -> Fail | H30: =IF(COUNTIFS($C$16:$C$27,"Must",H16:H27,0)=0,"Pass","Fail") -> Pass
B31: Recommendation | F31: =IF(F30="Pass",IF(F29>=Assumptions!$B$10,"Shortlist","Hold"),"Reject") -> Shortlist | G31: =IF(G30="Pass",IF(G29>=Assumptions!$B$10,"Shortlist","Hold"),"Reject") -> Reject | H31: =IF(H30="Pass",IF(H29>=Assumptions!$B$10,"Shortlist","Hold"),"Reject") -> Shortlist
B33: Weights: Must = 5, Preferred = 2 (editable). Flags: 1 = evidence found in public profile, 0 = not found. Shortlist threshold is set on the Assumptions sheet.

Sheet Sourcing Strategy
A1: Sourcing strategy: Associate GenAI Engineer (sample job order)
A3: 1. Channels and what to look for
A4: Channel | B4: What to look for | C4: Public signal | D4: Tactic
A5: LinkedIn (Recruiter / search) | B5: Python + LLM / RAG keywords, recent GenAI projects | C5: Headline, skills, project and experience sections | D5: Boolean search, save searches, filter by location and graduation year
A6: GitHub | B6: Repos with RAG, agents or FastAPI services; recent commits | C6: Stars, README quality, deployment links | D6: Search by topic and language; shortlist active contributors, then find them on LinkedIn
A7: Hugging Face / Kaggle | B7: Spaces, models, notebooks and competition ranks | C7: Public profile, activity | D7: Look for deployed Spaces and notebook quality
A8: Hackathon and community lists | B8: Winners and finalists at GenAI hackathons and meetups | C8: Event result pages, speaker lists | D8: Track local events; reach out with specific congratulations on the project
A9: Feeder companies | B9: Teams building similar products (see section 3) | C9: Employee lists, public posts | D9: Map teams, then target people 1-3 years in with a growth ceiling
A10: Campus and alumni networks | B10: Final-year and recent grads with AI projects | C10: College clubs, project showcases | D10: Partner with placement cells and alumni groups
A11: Referrals | B11: Strong candidates know others | C11: Existing shortlist | D11: Ask every screened candidate for two names
A13: 2. Boolean search strings (LinkedIn)
A14: Role | B14: Search string | C14: Notes
A15: GenAI / LLM Engineer (R1) | B15: ("generative AI" OR "LLM" OR "large language model" OR "GenAI") AND (Python) AND (RAG OR "vector database" OR LangChain OR LlamaIndex OR "OpenAI API") AND (Bengaluru OR Bangalore) NOT (intern OR recruiter OR "project manager") | C15: Drop NOT intern when sourcing freshers
A16: ML Engineer / MLOps (R2) | B16: ("machine learning engineer" OR "ML engineer" OR MLOps) AND (Python) AND (PyTorch OR TensorFlow) AND (Docker OR Kubernetes OR MLflow OR "model deployment") AND (India) | C16: Add cloud keyword for the client stack
A17: Data Scientist (R3) | B17: ("data scientist" OR "decision scientist") AND (Python) AND (SQL) AND ("machine learning" OR statistics OR "A/B testing") NOT (manager OR director) | C17: Add domain keyword for the client's industry
A18: Data Engineer (R4) | B18: ("data engineer" OR "analytics engineer") AND (SQL) AND (Spark OR Airflow OR dbt OR Databricks) AND (AWS OR Azure OR GCP) | C18: Add warehouse tools: Snowflake, BigQuery
A19: ServiceNow Developer (R5) | B19: (ServiceNow) AND (developer OR "platform engineer") AND (GlideScript OR "Flow Designer" OR "Service Portal" OR ITSM) AND (CAD OR CSA OR "Certified Application Developer") | C19: Also search the ServiceNow Community profile pages
A20: AI Product Manager (R6) | B20: ("product manager" OR "associate product manager" OR "product analyst") AND (AI OR ML OR "generative AI" OR platform) AND (roadmap OR PRD OR "user research") | C20: Check for shipped features in public posts
A21: Solutions Consultant (R7) | B21: ("solutions engineer" OR "solutions consultant" OR "pre-sales" OR "technical consultant") AND (SaaS OR cloud OR AI) AND (demo OR "proof of concept" OR POC) | C21: Look for client-facing language in summaries
A23: 3. Feeder companies (where to look first, by role)
A24: Role | B24: Feeder companies (from the Companies sheet) | C24: Why
A25: GenAI / LLM Engineer (R1) | B25: Leena AI, Yellow.ai, Observe.AI, Uniphore, Sarvam AI, Gnani.ai, Haptik, Krutrim | C25: Teams already shipping LLM products; candidates have production exposure
A26: ML Engineer / MLOps (R2) | B26: Razorpay, Postman, Walmart Global Tech, Tredence, Tiger Analytics | C26: Strong engineering culture with deployment practice
A27: Data Scientist (R3) | B27: Fractal Analytics, LatentView, Tiger Analytics, Razorpay | C27: Large analytics benches, fast promotion cycles
A28: Data Engineer (R4) | B28: Infosys, TCS, Wipro, Accenture, Chargebee, Walmart Global Tech | C28: Volume pipelines of data engineering talent
A29: ServiceNow Developer (R5) | B29: Deloitte, Accenture, TCS, Infosys, Wipro, HCLTech, Cognizant, Capgemini | C29: Biggest ServiceNow partner benches in India
A30: AI Product Manager (R6) | B30: Freshworks, Zoho, Atlassian, Whatfix, Darwinbox | C30: Product-led SaaS with APM-style pathways
A31: Solutions Consultant (R7) | B31: Freshworks, Whatfix, Fractal Analytics, Capgemini, Deloitte | C31: Client-facing, demo-heavy roles
A33: 4. Funnel model | B33: Assumptions based on data scraped
A34: Profiles identified | B34: 200
A35: Contact rate | B35: 0.8
A36: Contacted | B36: =ROUND(B34*B35,0) -> 160
A37: Reply rate | B37: 0.25
A38: Replies | B38: =ROUND(B36*B37,0) -> 40
A39: Screen-to-interested rate | B39: 0.5
A40: Screened (interested) | B40: =ROUND(B38*B39,0) -> 20
A41: Pass technical screen rate | B41: 0.4
A42: Shortlist sent to client | B42: =ROUND(B40*B41,0) -> 8
A43: Profiles needed per shortlisted candidate | B43: =IF(B42=0,0,ROUND(B34/B42,1)) -> 25
A45: 5. Outreach message template (research-led, short)
...

Sheet Insights
A1: Hiring patterns: formula-driven from the Companies sheet
A3: By company type
A4: Type | B4: # Companies | C4: Avg fit score | D4: Avg agency openness
A5: Platform vendor | B5: =COUNTIF(Companies!$D$2:$D$45,A5) -> 8 | C5: =IFERROR(AVERAGEIF(Companies!$D$2:$D$45,A5,Companies!$P$2:$P$45),0) -> 3.29 | D5: =IFERROR(AVERAGEIF(Companies!$D$2:$D$45,A5,Companies!$I$2:$I$45),0) -> 1.75
A6: SaaS product | B6: =COUNTIF(Companies!$D$2:$D$45,A6) -> 13 | C6: =IFERROR(AVERAGEIF(Companies!$D$2:$D$45,A6,Companies!$P$2:$P$45),0) -> 2.8815385 | D6: =IFERROR(AVERAGEIF(Companies!$D$2:$D$45,A6,Companies!$I$2:$I$45),0) -> 2.6923077
A7: AI SaaS | B7: =COUNTIF(Companies!$D$2:$D$45,A7) -> 4 | C7: =IFERROR(AVERAGEIF(Companies!$D$2:$D$45,A7,Companies!$P$2:$P$45),0) -> 3.16 | D7: =IFERROR(AVERAGEIF(Companies!$D$2:$D$45,A7,Companies!$I$2:$I$45),0) -> 3.5
A8: AI startup | B8: =COUNTIF(Companies!$D$2:$D$45,A8) -> 5 | C8: =IFERROR(AVERAGEIF(Companies!$D$2:$D$45,A8,Companies!$P$2:$P$45),0) -> 2.96 | D8: =IFERROR(AVERAGEIF(Companies!$D$2:$D$45,A8,Companies!$I$2:$I$45),0) -> 4
A9: IT services | B9: =COUNTIF(Companies!$D$2:$D$45,A9) -> 9 | C9: =IFERROR(AVERAGEIF(Companies!$D$2:$D$45,A9,Companies!$P$2:$P$45),0) -> 3.7355556 | D9: =IFERROR(AVERAGEIF(Companies!$D$2:$D$45,A9,Companies!$I$2:$I$45),0) -> 3
A10: Analytics & AI services | B10: =COUNTIF(Companies!$D$2:$D$45,A10) -> 4 | C10: =IFERROR(AVERAGEIF(Companies!$D$2:$D$45,A10,Companies!$P$2:$P$45),0) -> 3.2925 | D10: =IFERROR(AVERAGEIF(Companies!$D$2:$D$45,A10,Companies!$I$2:$I$45),0) -> 3.75
A11: GCC | B11: =COUNTIF(Companies!$D$2:$D$45,A11) -> 1 | C11: =IFERROR(AVERAGEIF(Companies!$D$2:$D$45,A11,Companies!$P$2:$P$45),0) -> 3.05 | D11: =IFERROR(AVERAGEIF(Companies!$D$2:$D$45,A11,Companies!$I$2:$I$45),0) -> 1
A12: Total | B12: =SUM(B5:B11) -> 44
A14: By primary India hub
A15: Hub | B15: # Companies | C15: Share
A16: Bengaluru | B16: =COUNTIF(Companies!$F$2:$F$45,A16) -> 20 | C16: =B16/COUNTA(Companies!$B$2:$B$45) -> 0.45454545
A17: Hyderabad | B17: =COUNTIF(Companies!$F$2:$F$45,A17) -> 5 | C17: =B17/COUNTA(Companies!$B$2:$B$45) -> 0.11363636
A18: Chennai | B18: =COUNTIF(Companies!$F$2:$F$45,A18) -> 7 | C18: =B18/COUNTA(Companies!$B$2:$B$45) -> 0.15909091
A19: NCR | B19: =COUNTIF(Companies!$F$2:$F$45,A19) -> 4 | C19: =B19/COUNTA(Companies!$B$2:$B$45) -> 0.090909091
A20: Mumbai | B20: =COUNTIF(Companies!$F$2:$F$45,A20) -> 6 | C20: =B20/COUNTA(Companies!$B$2:$B$45) -> 0.13636364
A21: Pune | B21: =COUNTIF(Companies!$F$2:$F$45,A21) -> 2 | C21: =B21/COUNTA(Companies!$B$2:$B$45) -> 0.045454545
A23: By size band
A24: Size band | B24: # Companies | C24: Share
A25: Large | B25: =COUNTIF(Companies!$G$2:$G$45,A25) -> 20 | C25: =B25/COUNTA(Companies!$B$2:$B$45) -> 0.45454545
A26: Mid | B26: =COUNTIF(Companies!$G$2:$G$45,A26) -> 18 | C26: =B26/COUNTA(Companies!$B$2:$B$45) -> 0.40909091
A27: Small | B27: =COUNTIF(Companies!$G$2:$G$45,A27) -> 6 | C27: =B27/COUNTA(Companies!$B$2:$B$45) -> 0.13636364
A29: Role demand (companies likely hiring each role)
A30: Role | B30: # Companies | C30: Share
A31: ='Roles & Skills'!B4 -> GenAI / LLM Engineer | B31: =COUNTIF(Companies!$H$2:$H$45,"*R1*") -> 38 | C31: =B31/COUNTA(Companies!$B$2:$B$45) -> 0.86363636
A32: ='Roles & Skills'!B5 -> ML Engineer / MLOps | B32: =COUNTIF(Companies!$H$2:$H$45,"*R2*") -> 39 | C32: =B32/COUNTA(Companies!$B$2:$B$45) -> 0.88636364
A33: ='Roles & Skills'!B6 -> Data Scientist | B33: =COUNTIF(Companies!$H$2:$H$45,"*R3*") -> 25 | C33: =B33/COUNTA(Companies!$B$2:$B$45) -> 0.56818182
A34: ='Roles & Skills'!B7 -> Data Engineer | B34: =COUNTIF(Companies!$H$2:$H$45,"*R4*") -> 27 | C34: =B34/COUNTA(Companies!$B$2:$B$45) -> 0.61363636
A35: ='Roles & Skills'!B8 -> ServiceNow Developer | B35: =COUNTIF(Companies!$H$2:$H$45,"*R5*") -> 10 | C35: =B35/COUNTA(Companies!$B$2:$B$45) -> 0.22727273
A36: ='Roles & Skills'!B9 -> AI Product Manager | B36: =COUNTIF(Companies!$H$2:$H$45,"*R6*") -> 24 | C36: =B36/COUNTA(Companies!$B$2:$B$45) -> 0.54545455
A37: ='Roles & Skills'!B10 -> Solutions Consultant / Pre-sales | B37: =COUNTIF(Companies!$H$2:$H$45,"*R7*") -> 23 | C37: =B37/COUNTA(Companies!$B$2:$B$45) -> 0.52272727

Sheet Client Prospects
A1: Top-10 potential client companies (auto-ranked by client fit score)
A2: Provisional until you fill Hiring signal on the Companies sheet. Weights live on the Assumptions sheet.
A4: Rank | B4: Company | C4: Type | D4: India hub | E4: Size band | F4: Fit score | G4: Likely roles | H4: Suggested outreach angle | I4: Companies row (helper)
A5: 1 | B5: =INDEX(Companies!$B$2:$B$45,$I5) -> Deloitte | C5: =INDEX(Companies!$D$2:$D$45,$I5) -> IT services | D5: =INDEX(Companies!$F$2:$F$45,$I5) -> Hyderabad | E5: =INDEX(Companies!$G$2:$G$45,$I5) -> Large | F5: =INDEX(Companies!$P$2:$P$45,$I5) -> 4.05 | G5: =INDEX(Companies!$H$2:$H$45,$I5) -> R1,R3,R5,R6,R7 | H5: =IFERROR(INDEX(Assumptions!$B$21:$B$27,MATCH(C5,Assumptions!$A$21:$A$27,0)),"") -> High volume, ServiceNow and data skills in constant demand. Pitch pipeline building and bench-to-billable matching. | I5: =MATCH(LARGE(Companies!$Q$2:$Q$45,A5),Companies!$Q$2:$Q$45,0) -> 35
A6: 2 | B6: =INDEX(Companies!$B$2:$B$45,$I6) -> Accenture | C6: =INDEX(Companies!$D$2:$D$45,$I6) -> IT services | D6: =INDEX(Companies!$F$2:$F$45,$I6) -> Bengaluru | E6: =INDEX(Companies!$G$2:$G$45,$I6) -> Large | F6: =INDEX(Companies!$P$2:$P$45,$I6) -> 4.03 | G6: =INDEX(Companies!$H$2:$H$45,$I6) -> R1,R2,R3,R4,R5,R7 | H6: =IFERROR(INDEX(Assumptions!$B$21:$B$27,MATCH(C6,Assumptions!$A$21:$A$27,0)),"") -> High volume, ServiceNow and data skills in constant demand. Pitch pipeline building and bench-to-billable matching. | I6: =MATCH(LARGE(Companies!$Q$2:$Q$45,A6),Companies!$Q$2:$Q$45,0) -> 36
A7: 3 | B7: =INDEX(Companies!$B$2:$B$45,$I7) -> Cognizant | C7: =INDEX(Companies!$D$2:$D$45,$I7) -> IT services | D7: =INDEX(Companies!$F$2:$F$45,$I7) -> Chennai | E7: =INDEX(Companies!$G$2:$G$45,$I7) -> Large | F7: =INDEX(Companies!$P$2:$P$45,$I7) -> 3.85 | G7: =INDEX(Companies!$H$2:$H$45,$I7) -> R1,R3,R4,R5,R7 | H7: =IFERROR(INDEX(Assumptions!$B$21:$B$27,MATCH(C7,Assumptions!$A$21:$A$27,0)),"") -> High volume, ServiceNow and data skills in constant demand. Pitch pipeline building and bench-to-billable matching. | I7: =MATCH(LARGE(Companies!$Q$2:$Q$45,A7),Companies!$Q$2:$Q$45,0) -> 41
A8: 4 | B8: =INDEX(Companies!$B$2:$B$45,$I8) -> TCS | C8: =INDEX(Companies!$D$2:$D$45,$I8) -> IT services | D8: =INDEX(Companies!$F$2:$F$45,$I8) -> Mumbai | E8: =INDEX(Companies!$G$2:$G$45,$I8) -> Large | F8: =INDEX(Companies!$P$2:$P$45,$I8) -> 3.83 | G8: =INDEX(Companies!$H$2:$H$45,$I8) -> R1,R2,R3,R4,R5,R7 | H8: =IFERROR(INDEX(Assumptions!$B$21:$B$27,MATCH(C8,Assumptions!$A$21:$A$27,0)),"") -> High volume, ServiceNow and data skills in constant demand. Pitch pipeline building and bench-to-billable matching. | I8: =MATCH(LARGE(Companies!$Q$2:$Q$45,A8),Companies!$Q$2:$Q$45,0) -> 37
A9: 5 | B9: =INDEX(Companies!$B$2:$B$45,$I9) -> Infosys | C9: =INDEX(Companies!$D$2:$D$45,$I9) -> IT services | D9: =INDEX(Companies!$F$2:$F$45,$I9) -> Bengaluru | E9: =INDEX(Companies!$G$2:$G$45,$I9) -> Large | F9: =INDEX(Companies!$P$2:$P$45,$I9) -> 3.83 | G9: =INDEX(Companies!$H$2:$H$45,$I9) -> R1,R2,R3,R4,R5,R7 | H9: =IFERROR(INDEX(Assumptions!$B$21:$B$27,MATCH(C9,Assumptions!$A$21:$A$27,0)),"") -> High volume, ServiceNow and data skills in constant demand. Pitch pipeline building and bench-to-billable matching. | I9: =MATCH(LARGE(Companies!$Q$2:$Q$45,A9),Companies!$Q$2:$Q$45,0) -> 38
A10: 6 | B10: =INDEX(Companies!$B$2:$B$45,$I10) -> ServiceNow | C10: =INDEX(Companies!$D$2:$D$45,$I10) -> Platform vendor | D10: =INDEX(Companies!$F$2:$F$45,$I10) -> Hyderabad | E10: =INDEX(Companies!$G$2:$G$45,$I10) -> Large | F10: =INDEX(Companies!$P$2:$P$45,$I10) -> 3.75 | G10: =INDEX(Companies!$H$2:$H$45,$I10) -> R1,R2,R5,R6,R7 | H10: =IFERROR(INDEX(Assumptions!$B$21:$B$27,MATCH(C10,Assumptions!$A$21:$A$27,0)),"") -> Low agency use, so pitch niche or hard-to-find talent pools (e.g. ServiceNow + GenAI hybrids), speed on specialist roles. | I10: =MATCH(LARGE(Companies!$Q$2:$Q$45,A10),Companies!$Q$2:$Q$45,0) -> 1
A11: 7 | B11: =INDEX(Companies!$B$2:$B$45,$I11) -> Wipro | C11: =INDEX(Companies!$D$2:$D$45,$I11) -> IT services | D11: =INDEX(Companies!$F$2:$F$45,$I11) -> Bengaluru | E11: =INDEX(Companies!$G$2:$G$45,$I11) -> Large | F11: =INDEX(Companies!$P$2:$P$45,$I11) -> 3.65 | G11: =INDEX(Companies!$H$2:$H$45,$I11) -> R1,R2,R4,R5,R7 | H11: =IFERROR(INDEX(Assumptions!$B$21:$B$27,MATCH(C11,Assumptions!$A$21:$A$27,0)),"") -> High volume, ServiceNow and data skills in constant demand. Pitch pipeline building and bench-to-billable matching. | I11: =MATCH(LARGE(Companies!$Q$2:$Q$45,A11),Companies!$Q$2:$Q$45,0) -> 39
A12: 8 | B12: =INDEX(Companies!$B$2:$B$45,$I12) -> Capgemini | C12: =INDEX(Companies!$D$2:$D$45,$I12) -> IT services | D12: =INDEX(Companies!$F$2:$F$45,$I12) -> Mumbai | E12: =INDEX(Companies!$G$2:$G$45,$I12) -> Large | F12: =INDEX(Companies!$P$2:$P$45,$I12) -> 3.65 | G12: =INDEX(Companies!$H$2:$H$45,$I12) -> R1,R2,R4,R5,R7 | H12: =IFERROR(INDEX(Assumptions!$B$21:$B$27,MATCH(C12,Assumptions!$A$21:$A$27,0)),"") -> High volume, ServiceNow and data skills in constant demand. Pitch pipeline building and bench-to-billable matching. | I12: =MATCH(LARGE(Companies!$Q$2:$Q$45,A12),Companies!$Q$2:$Q$45,0) -> 42
A13: 9 | B13: =INDEX(Companies!$B$2:$B$45,$I13) -> Salesforce | C13: =INDEX(Companies!$D$2:$D$45,$I13) -> Platform vendor | D13: =INDEX(Companies!$F$2:$F$45,$I13) -> Hyderabad | E13: =INDEX(Companies!$G$2:$G$45,$I13) -> Large | F13: =INDEX(Companies!$P$2:$P$45,$I13) -> 3.55 | G13: =INDEX(Companies!$H$2:$H$45,$I13) -> R1,R2,R3,R6,R7 | H13: =IFERROR(INDEX(Assumptions!$B$21:$B$27,MATCH(C13,Assumptions!$A$21:$A$27,0)),"") -> Low agency use, so pitch niche or hard-to-find talent pools (e.g. ServiceNow + GenAI hybrids), speed on specialist roles. | I13: =MATCH(LARGE(Companies!$Q$2:$Q$45,A13),Companies!$Q$2:$Q$45,0) -> 2
A14: 10 | B14: =INDEX(Companies!$B$2:$B$45,$I14) -> Fractal Analytics | C14: =INDEX(Companies!$D$2:$D$45,$I14) -> Analytics & AI services | D14: =INDEX(Companies!$F$2:$F$45,$I14) -> Mumbai | E14: =INDEX(Companies!$G$2:$G$45,$I14) -> Mid | F14: =INDEX(Companies!$P$2:$P$45,$I14) -> 3.53 | G14: =INDEX(Companies!$H$2:$H$45,$I14) -> R1,R2,R3,R4,R6,R7 | H14: =IFERROR(INDEX(Assumptions!$B$21:$B$27,MATCH(C14,Assumptions!$A$21:$A$27,0)),"") -> Project-driven hiring spikes. Pitch flexible capacity and pre-vetted data / ML pools. | I14: =MATCH(LARGE(Companies!$Q$2:$Q$45,A14),Companies!$Q$2:$Q$45,0) -> 31

Sheet Assumptions
A1: Assumptions & lookup tables
A3: Client-fit score weights
A4: Size score weight | B4: 0.25
A5: Role breadth weight | B5: 0.25
A6: Agency openness weight | B6: 0.3
A7: Hiring signal weight | B7: 0.2
A8: Weights check (must equal 100%) | B8: =SUM(B4:B7) -> 1
A9: Default hiring signal if blank (1-5) | B9: 3
A10: Shortlist threshold (candidate scorecard) | B10: 0.75
A12: Size band -> size score (bigger = more hiring volume)
A13: Large | B13: 5
A14: Mid | B14: 3
A15: Small | B15: 2
A17: Size band definitions (global headcount): Large = 10,000+, Mid = 1,000-10,000, Small = under 1,000. Estimates.
A19: Outreach angle by company type
A20: Company type | B20: Suggested outreach angle
A21: Platform vendor | B21: Low agency use, so pitch niche or hard-to-find talent pools (e.g. ServiceNow + GenAI hybrids), speed on specialist roles.
A22: SaaS product | B22: Growing teams, lean TA. Pitch full-cycle support for engineering and product hires plus market mapping.
A23: AI SaaS | B23: Scarce GenAI talent and fast scaling. Pitch pre-mapped candidate pools and compensation benchmarking.
A24: AI startup | B24: No in-house TA at scale. Pitch embedded recruiting and rapid shortlists for first-10 / first-50 hires.
A25: IT services | B25: High volume, ServiceNow and data skills in constant demand. Pitch pipeline building and bench-to-billable matching.
A26: Analytics & AI services | B26: Project-driven hiring spikes. Pitch flexible capacity and pre-vetted data / ML pools.
A27: GCC | B27: Strong brand, India build-out. Pitch niche leadership and senior IC mapping, plus competitor talent maps.

Sheet Market Report
A1: Talent Market Report: Enterprise AI / GenAI & SaaS (India)
A2: Scope and method
A3: ="This report maps "&COUNTA(Companies!$B$2:$B$45)&" employers across "&COUNTA(Insights!$A$5:$A$11)&" company types, compares 7 job roles over 21 skills, and ranks potential client companies using a transparent weighted score. Company attributes are desk-research estimates; live hiring signals are to be added from careers pages and LinkedIn." -> This report maps 44 employers across 7 company types, compares 7 job roles over 21 skills, and ranks potential client companies using a transparent weighted score. Company attributes are desk-research estimates; live hiring signals are to be added from careers pages and LinkedIn.
A4: Headline numbers (update automatically)
A5: ="Most common role across the database: "&INDEX(Insights!$A$31:$A$37,MATCH(MAX(Insights!$B$31:$B$37),Insights!$B$31:$B$37,0))&" ("&MAX(Insights!$B$31:$B$37)&" of "&COUNTA(Companies!$B$2:$B$45)&" companies likely hiring it)." -> Most common role across the database: ML Engineer / MLOps (39 of 44 companies likely hiring it).
A6: ="Largest hub: "&INDEX(Insights!$A$16:$A$21,MATCH(MAX(Insights!$B$16:$B$21),Insights!$B$16:$B$21,0))&" with "&MAX(Insights!$B$16:$B$21)&" companies ("&TEXT(MAX(Insights!$B$16:$B$21)/COUNTA(Companies!$B$2:$B$45),"0%")&" of the database)." -> Largest hub: Bengaluru with 20 companies (45% of the database).
A7: ="Highest-fit prospect right now: "&'Client Prospects'!B5&" (score "&TEXT('Client Prospects'!F5,"0.00")&"), followed by "&'Client Prospects'!B6&" and "&'Client Prospects'!B7&"." -> Highest-fit prospect right now: Deloitte (score 4.05), followed by Accenture and Cognizant.
A8: Hiring patterns
A9: 1. AI demand is growing while general IT hiring is flat. One secondary source puts AI-role hiring in India up about 32% in 2026, and Naukri JobSpeak figures cited by another show Indian MNCs growing AI/ML hiring 82% year on year (treat both as indicative). GenAI skills are now table stakes across company types. LLM APIs, RAG and agent frameworks show up as must-haves for GenAI engineers and as preferred skills for product and solutions roles. Candidates with deployed projects stand out far more than coursework alone.
A10: 2. Large IT services firms are hiring selectively, not in volume. Reports show the top five (TCS, Infosys, Wipro, HCLTech, Tech Mahindra) cut headcount by roughly 7,000 in FY26, TCS trimmed its FY27 fresher plan to about 25,000 from 40,000+, and Infosys held at about 20,000. Demand has shifted toward AI, cloud and data skills, and Accenture is visibly posting GenAI and AI/ML roles for 0-2 year candidates. ServiceNow work continues across the partner ecosystem, with CAD / CSA as the clearest screening signal.
A11: 3. Product and platform companies hire fewer people with a higher bar. They rely on brand and campus pipelines, so agency openness is lower. The opening for recruiters is niche, senior or hard-to-find profiles.
A12: 4. AI startups and AI SaaS firms are the most agency-friendly. Small TA teams, fast scaling and scarce GenAI talent make research-led mapping valuable to them, but their small size means fewer roles per account.
A13: 5. Bengaluru dominates, but Hyderabad, Chennai and the NCR are significant secondary hubs (see the hub table on the Insights sheet). Location strategy should be role-specific, not city-wide.
A14: 6. Verified India openings skew senior. Freshworks' official board lists 28 India roles, almost all Senior, Staff, Lead or Principal. Sarvam AI lists 61 positions, about half engineering, mostly on-site in Bengaluru. ServiceNow lists 71 India jobs. Entry-level seats are scarcer than headline hiring numbers suggest, which strengthens the case for pre-vetted junior pipelines.
A15: 7. Some targets are closed to agencies. Postman's job posts say it does not accept unsolicited agency resumes or pay fees without a signed agreement, so the outreach angle there is a formal vendor-onboarding conversation, not a cold CV drop. Check each prospect's policy before outreach.
A16: Potential clients and outreach approach
A17: The scoring favours large IT services firms (volume plus role breadth), so they rank highest, even though their hiring is now selective and skills-led. AI startups and AI SaaS firms (Leena AI, Yellow.ai, Observe.AI, Sarvam AI, Gnani.ai, Haptik) rank lower on size but are the most open to agencies, so they suit embedded or project-based search. Mid-size SaaS (Freshworks, Postman, Darwinbox, Whatfix) sits in between for engineering and product roles. Pick the lead segment by goal: volume or fit.
A18: Outreach should be research-led: reference the company's visible hiring signals, offer a pre-mapped candidate pool for one role, and attach a short market snapshot. The full ranked list and angles are on the Client Prospects sheet.
A19: Limitations and next steps
A20: ="Hiring signal is filled for "&COUNT(Companies!$J$2:$J$45)&" of "&COUNTA(Companies!$B$2:$B$45)&" companies, using news and job-listing evidence (see Sources). Fill the rest from live careers pages, re-rank, and re-validate the skills matrix against five live job descriptions per role. Treat the ranking as a working hypothesis, not a finding." -> Hiring signal is filled for 19 of 44 companies, using news and job-listing evidence (see Sources). Fill the rest from live careers pages, re-rank, and re-validate the skills matrix against five live job descriptions per role. Treat the ranking as a working hypothesis, not a finding.

Sheet Sources
A1: Evidence log (searched 25 Oct 2026)
A3: ID | B3: Used for | C3: Source | D3: Quality | E3: URL
A4: S1 | B4: Accenture GenAI fresher hiring push (FY26) | C4: FACE Prep: Accenture recruitment 2026 | D4: Secondary (prep site) | E4: https://faceprep.in/article/accenture-recruitment-2026-eligibility-and-exam-pattern/
A5: S2 | B5: Accenture LLM Full Stack Engineer fresher opening | C5: Freshershunt listing | D5: Aggregator (verify on official portal) | E5: https://freshershunt.in/accenture-llm-full-stack-engineer-freshers-hiring-2026/
A6: S3 | B6: Accenture Data Science Associate and AI/ML Associate openings | C6: Yohire / Enggwave listings | D6: Aggregator (verify on official portal) | E6: https://yohire.in/job/accenture-india-hiring-2026-1791518412
A7: S3b | B7: Accenture AI/ML Engineer opening (Jul 2026) | C7: Enggwave | D7: Aggregator (verify on official portal) | E7: https://www.enggwave.com/accenture-ai-ml-engineer-recruitment-2026/108432
A8: S4 | B8: Top-five IT headcount fell ~7,000 in FY26; TCS FY27 fresher plan ~25k | C8: IANS | D8: News agency | E8: https://ianslive.in/top-it-firms-hiring-turns-negative-as-headcount-falls-over-7000-in-fy26--20260425104000
A9: S4b | B9: Infosys plans ~20,000 freshers in FY27 | C9: Outlook Business | D9: News | E9: https://www.outlookbusiness.com/corporate/infosys-plans-to-hire-20000-freshers-in-fy27-even-as-quarterly-headcount-dips
A10: S4c | B10: Q1 FY27 headcount moves: Infosys, TechM, HCLTech, TCS, Wipro | C10: Entrepreneur India / NewsBytes | D10: News | E10: https://india.entrepreneur.com/?p=98410
A11: S5 | B11: Sarvam AI funding and expected hiring | C11: CareerIndia | D11: Secondary (career news site) | E11: https://www.careerindia.com/news/sarvam-ai-hiring-2026-valuation-indus-rollout-top-paying-roles-011-67035.html
A12: S5b | B12: Sarvam AI Series B first close, India AI talent pricing | C12: Asanify AI news digest | D12: Secondary | E12: https://asanify.com/blog/news/india-foundation-model-funding-june-29-2026/
A13: S6 | B13: ServiceNow Hyderabad Software Engineer fresher drive | C13: Freshers Recruitment / Cloud Soft Solutions | D13: Aggregator (verify on careers.servicenow.com) | E13: https://freshersrecruitment.co.in/?p=4883
A14: S7 | B14: AI-role hiring in India up ~32% in 2026; top roles | C14: GradRight | D14: Secondary, indicative only | E14: https://gradright.com/?p=49969
... A29: S8 | B29: ServiceNow developer demand at Accenture, Hyderabad | C29: Career.io listing | D29: Aggregator | E29: https://career.io/job/servicenow-developer-hyderabad-grow-your-staff-04b87560f7f212726cfd5d2495b450db
A31: Note: 25 companies still have no hiring evidence (not checked or nothing retrievable without a login). Searches for Zoho returned nothing current, so their signals stay blank rather than guessed. LinkedIn Jobs needs a login, so I could not read it.

Sheet Resume Bullets
A1: Talent Market Mapping & Recruitment Research | Excel, LinkedIn, Desk Research
A3: ="Conducted structured research across "&COUNTA(Companies!$B$2:$B$45)&" companies in the Enterprise AI / GenAI & SaaS sector (India) to map hiring activity, common job roles and in-demand skills, and verified live hiring signals for "&COUNT(Companies!$J$2:$J$45)&" of them using careers pages, applicant-tracking boards and news sources." -> Conducted structured research across 44 companies in the Enterprise AI / GenAI & SaaS sector (India) to map hiring activity, common job roles and in-demand skills, and verified live hiring signals for 19 of them using careers pages, applicant-tracking boards and news sources.
